Workbook

Sheet Leggimi
B1: DCF didattico — Alfa S.p.A. (azienda inventata)
B2: Un modello Discounted Cash Flow piccolo ma completo, costruito per studiare ogni passaggio. Tutti i numeri sono inventati.
B4: 1. L'idea in tre righe
B5: Un'azienda vale quanto la cassa che produrrà in futuro per chi l'ha finanziata, riportata a oggi. Un euro di domani vale meno di un euro di oggi (potrei investirlo nel frattempo, e non è certo che arrivi): per questo ogni flusso futuro viene "scontato" a un tasso che riflette il rischio.
B6: Formula generale: Enterprise Value = Σ FCFF(t) / (1 + WACC)^t + Terminal Value / (1 + WACC)^n
B7: Tre ingredienti, quindi: i flussi di cassa (FCFF), il tasso di sconto (WACC) e il valore oltre l'orizzonte di piano (Terminal Value). Il resto del modello serve solo a costruire questi tre numeri in modo coerente.
B9: 2. I passi del DCF e dove trovarli
B10: Passo | C10: Cosa si fa | D10: Foglio | E10: Formula chiave
B11: 0. Storico | C11: Si leggono CE, SP e RF degli ultimi anni e si calcolano gli indicatori (crescita, margini, giorni di circolante) su cui basare le ipotesi. | D11: CE, SP, RF | E11: Indicatori storici nel foglio Ipotesi, colonne B-D
B12: 1. Ipotesi | C12: Si decide come evolveranno ricavi, margini, investimenti e circolante nei prossimi 5 anni. | D12: Ipotesi | E12: Celle blu: sono le uniche da modificare
B13: 2. Proiezioni | C13: Si proiettano i tre prospetti. Lo SP deve quadrare e la cassa finale del RF deve coincidere con la cassa dello SP. | D13: CE, SP, RF | E13: Attivo = Passivo + PN; Cassa finale = Cassa iniziale + Flussi
B14: 3. FCFF | C14: Si calcola il flusso di cassa operativo disponibile per tutti i finanziatori (azionisti e creditori). | D14: DCF (passo 1) | E14: FCFF = EBIT × (1 − t) + Ammortamenti − Capex − ΔCCN
B15: 4. WACC | C15: Si stima il tasso di sconto: media ponderata del costo dell'equity (CAPM) e del costo del debito dopo le imposte. | D15: WACC | E15: WACC = E/(D+E) × Ke + D/(D+E) × Kd × (1 − t)
B16: 5. Attualizzazione | C16: Ogni flusso viene moltiplicato per il suo fattore di sconto. | D16: DCF (passo 2) | E16: VA = FCFF(t) / (1 + WACC)^t
B17: 6. Terminal Value | C17: Si stima il valore di tutti i flussi dopo il 2030 con la rendita perpetua crescente (Gordon) e lo si sconta a oggi. | D17: DCF (passo 3) | E17: TV = FCFF(n) × (1 + g) / (WACC − g)
B18: 7. Da EV a prezzo | C18: Dal valore dell'attività si toglie il debito netto: resta il valore per gli azionisti, da dividere per il numero di azioni. | D18: DCF (passo 4) | E18: Equity Value = EV − PFN; Valore per azione = Equity / n. azioni
B19: 8. Controlli | C19: Si verifica che il risultato sia ragionevole (peso del TV, multipli impliciti) e quanto è sensibile a WACC e g. | D19: DCF (passo 5), Sensitività | E19: TV / EV; EV / EBITDA; tabella WACC × g
B21: 3. Come leggere il file
B22: Testo blu | C22: Dato inserito a mano (storico o ipotesi). Sono le uniche celle da cambiare.
B23: Testo nero | C23: Formula: si ricalcola da sola. Clicca sulla cella per vedere la formula Excel vera.
B24: Testo verde | C24: Collegamento a un altro foglio (il numero viene da lì, senza calcoli).
B25: Sfondo giallo | C25: Ipotesi che pesano di più sul valore: sono quelle da discutere.
B26: Sfondo verde | C26: Risultati principali.
B27: Unità: milioni di euro, salvo percentuali, giorni e valori per azione. "A" = actual (consuntivo), "E" = expected (previsione).
B28: Ogni colonna è lo stesso anno in tutti i fogli (la colonna E è sempre il 2026): è una regola di buona modellazione che rende le formule facili da controllare.
B29: Segni: nel CE i costi sono scritti positivi e sottratti (voci con "(−)"). Nel RF e nel DCF invece i flussi hanno il loro segno: entrate positive, uscite negative (tra parentesi), così ogni totale è una semplice somma.
B30: Accanto a ogni riga trovi la formula a parole (colonna K) e la spiegazione (colonna L).
B32: 4. Esercizi per capire (cambia una cella blu e osserva cosa succede)
B33: a) Ipotesi → crescita perpetua g dal 2,0% al 3,0%. Di quanto sale il valore per azione? Guarda nel foglio DCF quanto pesa il Terminal Value: capirai perché g è l'ipotesi più delicata.
B34: b) Ipotesi → beta unlevered da 0,90 a 1,10. Segui la catena nel foglio WACC: beta levered → Ke → WACC → fattori di sconto → valore.
B35: c) Ipotesi → giorni di incasso (DSO) da 60 a 75 in tutti gli anni. L'utile netto non cambia, il FCFF sì. Perché? (Risposta: il circolante assorbe cassa.)
B36: d) Ipotesi → rimborso del debito a 0 oppure payout al 100%. SP e RF cambiano, l'Enterprise Value no. Perché? (Risposta: il FCFF è calcolato prima di interessi, rimborsi e dividendi; le scelte di finanziamento entrano solo dal WACC.)
B37: e) Ipotesi → capex al 5,0% dei ricavi (uguale agli ammortamenti). Il valore sale, ma le immobilizzazioni restano ferme mentre i ricavi crescono: è credibile?
B38: f) Ipotesi → EBITDA margin −1 punto in tutti gli anni. Confronta l'effetto con quello di +0,5% sul WACC: quale leva pesa di più?
B40: 5. Cosa è stato semplificato rispetto a un DCF reale
... B47: • Un solo metodo. Un DCF serio viene sempre confrontato con i multipli di mercato di società comparabili.

Sheet Ipotesi
A1: Ipotesi
A2: A sinistra gli indicatori storici (calcolati dai bilanci), a destra le ipotesi per il piano (celle blu: modificabili).
B3: STORICO (dati di bilancio) | E3: PREVISIONE (piano a 5 anni)
A4: € milioni | B4: 2023A | C4: 2024A | D4: 2025A | E4: 2026E | F4: 2027E | G4: 2028E | H4: 2029E | I4: 2030E | K4: Formula (a parole) | L4: Spiegazione: cosa significa e perché si fa così
A5: A. Ipotesi operative e finanziarie (per anno)
A6: Crescita dei ricavi | B6: n.d. | C6: =CE!C5/CE!B5-1 -> 0.075 | D6: =CE!D5/CE!C5-1 -> 0.069767442 | E6: 0.06 | F6: 0.055 | G6: 0.05 | H6: 0.04 | I6: 0.03 | K6: Ricavi(t) / Ricavi(t−1) − 1 | L6: È il motore del modello: quasi tutte le altre voci sono legate ai ricavi. La crescita rallenta gradualmente verso il tasso di lungo periodo g: nessuna azienda cresce per sempre più dell'economia.
A7: EBITDA margin | B7: =CE!B7/CE!B5 -> 0.19 | C7: =CE!C7/CE!C5 -> 0.19534884 | D7: =CE!D7/CE!D5 -> 0.2 | E7: 0.2 | F7: 0.205 | G7: 0.21 | H7: 0.21 | I7: 0.21 | K7: EBITDA / Ricavi | L7: Redditività operativa prima di ammortamenti, interessi e imposte. Si parte dallo storico (19-20%) e si ipotizza un lieve miglioramento. Con la crescita, è l'ipotesi operativa che pesa di più sul valore.
A8: Ammortamenti (% dei ricavi) | B8: =CE!B8/CE!B5 -> 0.05 | C8: =CE!C8/CE!C5 -> 0.05 | D8: =CE!D8/CE!D5 -> 0.05 | E8: 0.05 | F8: 0.05 | G8: 0.05 | H8: 0.05 | I8: 0.05 | K8: Ammortamenti / Ricavi | L8: Gli ammortamenti sono un costo senza uscita di cassa: riducono l'utile (e le imposte) ma verranno riaggiunti nel calcolo del flusso di cassa.
A9: Investimenti - Capex (% dei ricavi) | B9: n.d. | C9: =-RF!C9/CE!C5 -> 0.061627907 | D9: =-RF!D9/CE!D5 -> 0.063043478 | E9: 0.06 | F9: 0.06 | G9: 0.055 | H9: 0.055 | I9: 0.055 | K9: Capex / Ricavi | L9: È la vera uscita di cassa per impianti e macchinari. In un'azienda che cresce il capex deve superare gli ammortamenti: non si può crescere consumando gli impianti senza sostituirli.
A10: Aliquota fiscale | B10: =CE!B12/CE!B11 -> 0.27967807 | C10: =CE!C12/CE!C11 -> 0.27915194 | D10: =CE!D12/CE!D11 -> 0.27987421 | E10: 0.28 | F10: 0.28 | G10: 0.28 | H10: 0.28 | I10: 0.28 | K10: Imposte / Utile ante imposte | L10: In Italia IRES 24% + IRAP 3,9% ≈ 28%. Nel DCF serve due volte: per le imposte "figurative" sull'EBIT e per lo scudo fiscale del debito dentro il WACC.
A11: Giorni di incasso crediti (DSO) | B11: =SP!B7/CE!B5*365 -> 60.225 | C11: =SP!C7/CE!C5*365 -> 60.267442 | D11: =SP!D7/CE!D5*365 -> 60.304348 | E11: 60 | F11: 60 | G11: 60 | H11: 60 | I11: 60 | K11: Crediti commerciali / Ricavi × 365 | L11: Tempo medio di incasso dai clienti. Più giorni = più cassa ferma nel circolante.
A12: Giorni di magazzino (DIO) | B12: =SP!B8/CE!B6*365 -> 45.061728 | C12: =SP!C8/CE!C6*365 -> 45.361272 | D12: =SP!D8/CE!D6*365 -> 44.633152 | E12: 45 | F12: 45 | G12: 45 | H12: 45 | I12: 45 | K12: Rimanenze / Costi operativi × 365 | L12: Tempo medio di permanenza delle scorte. Si rapporta ai costi (non ai ricavi) perché il magazzino è valutato al costo.
A13: Giorni di pagamento fornitori (DPO) | B13: =SP!B12/CE!B6*365 -> 69.845679 | C13: =SP!C12/CE!C6*365 -> 69.624277 | D13: =SP!D12/CE!D6*365 -> 70.421196 | E13: 70 | F13: 70 | G13: 70 | H13: 70 | I13: 70 | K13: Debiti commerciali / Costi operativi × 365 | L13: Tempo medio di pagamento ai fornitori. È un finanziamento senza interessi: più giorni = meno circolante da finanziare.
A14: Tasso di interesse sul debito | B14: n.d. | C14: =CE!C10/SP!B13 -> 0.045384615 | D14: =CE!D10/SP!C13 -> 0.045 | E14: 0.045 | F14: 0.045 | G14: 0.045 | H14: 0.045 | I14: 0.045 | K14: Oneri finanziari(t) / Debito(t−1) | L14: Serve per CE e RF. Attenzione: gli interessi NON entrano nel FCFF, perché il costo del debito è già dentro il tasso di sconto (WACC). Sarebbe il ROD, anche se quest'ultimo di solito si calcola sul debito medio o di fine anno.
A15: Rimborso del debito (€ mln) | B15: n.d. | C15: =-RF!C11 -> 10 | D15: =-RF!D11 -> 10 | E15: 10 | F15: 10 | G15: 10 | H15: 10 | I15: 10 | K15: Debito(t−1) − Debito(t) | L15: Quota di debito restituita ogni anno. Come gli interessi, riguarda il rapporto con i finanziatori e non tocca il FCFF.
A16: Payout (dividendi / utile netto) | B16: n.d. | C16: =-RF!C12/CE!C13 -> 0.39215686 | D16: =-RF!D12/CE!D13 -> 0.3930131 | E16: 0.4 | F16: 0.4 | G16: 0.4 | H16: 0.4 | I16: 0.4 | K16: Dividendi / Utile netto | L16: Quota di utile distribuita agli azionisti. Non influenza il valore nel DCF: serve solo a proiettare patrimonio netto e cassa.
A18: B. Ipotesi di valutazione | B18: Valore
A19: Data di valutazione | B19: 31/12/2025 | L19: Il "giorno zero" a cui si riportano tutti i flussi. Qui coincide con l'ultima chiusura di bilancio, così il flusso 2026 dista esattamente 1 anno.
A20: Crescita perpetua (g) | B20: 0.02 | L20: Crescita dei flussi dal 2031 all'infinito. Due vincoli: non oltre la crescita nominale di lungo periodo dell'economia (inflazione + crescita reale, in area euro 1,5-2,5%) e sempre minore del WACC, altrimenti la formula del Terminal Value non ha senso.
A21: Numero di azioni (milioni) | B21: 50 | L21: Azioni in circolazione. In un caso reale si usano le azioni diluite (incluse stock option e convertibili).
A22: Prezzo di mercato per azione (€) | B22: 14.5 | L22: Serve solo per il confronto finale: il DCF dice quanto "dovrebbe" valere l'azione, il mercato quanto vale oggi.
A24: C. Ipotesi per il WACC | B24: Valore
A25: Tasso privo di rischio (Rf) | B25: 0.035 | L25: Rendimento di un titolo di Stato a 10 anni nella valuta dei flussi (BTP o Bund, a seconda di dove si vuole mettere il rischio paese).
A26: Premio per il rischio di mercato (ERP) | B26: 0.055 | L26: Rendimento in più che gli investitori chiedono per tenere azioni invece di titoli privi di rischio. Stime usuali tra 4,5% e 6% (Damodaran, Fernandez).
A27: Beta unlevered (βu) | B27: 0.9 | L27: Beta "ripulito" dal debito: misura solo il rischio del business. Di solito è la media dei beta di società comparabili, ciascuno depurato dalla propria leva.
A28: Peso del debito obiettivo D / (D + E) | B28: 0.15 | L28: Struttura finanziaria obiettivo a valori di mercato, non quella contabile di oggi: il WACC deve valere per tutta la vita dell'azienda. Si usa un obiettivo anche per evitare la circolarità (il peso dell'equity dipenderebbe dal valore che stiamo cercando).
A29: Costo del debito lordo (Kd) | B29: 0.045 | L29: Tasso a cui l'azienda si finanzierebbe oggi (tasso privo di rischio + spread di credito). Qui è uguale al tasso pagato sul debito esistente. Spesso nella pratica il ROD si usa come approssimazione del Kd quando non si ha di meglio. Ma possono divergere parecchio: un'azienda che si è indebitata a tasso fisso nel 2021 ha un ROD basso, mentre il suo Kd di oggi è più alto. In quel caso nel WACC va il tasso di oggi. Per stimare il Kd in un caso reale, in ordine di preferenza: 1. Il rendimento a scadenza delle obbligazioni quotate della società. 2. Il risk-free più lo spread tipico del suo rating. 3. Il ROD, come ripiego.

Sheet CE
A1: Conto economico (CE)
A2: Alfa S.p.A. — dati inventati. Storico in blu (inserito a mano), previsione calcolata dalle ipotesi.
B3: STORICO (dati di bilancio) | E3: PREVISIONE (piano a 5 anni)
A4: € milioni | B4: 2023A | C4: 2024A | D4: 2025A | E4: 2026E | F4: 2027E | G4: 2028E | H4: 2029E | I4: 2030E | K4: Formula (a parole) | L4: Spiegazione: cosa significa e perché si fa così
A5: Ricavi | B5: 400 | C5: 430 | D5: 460 | E5: =D5*(1+Ipotesi!E6) -> 487.6 | F5: =E5*(1+Ipotesi!F6) -> 514.418 | G5: =F5*(1+Ipotesi!G6) -> 540.1389 | H5: =G5*(1+Ipotesi!H6) -> 561.74446 | I5: =H5*(1+Ipotesi!I6) -> 578.59679 | K5: Ricavi(t−1) × (1 + crescita) | L5: Ogni anno parte dai ricavi dell'anno precedente e applica la crescita ipotizzata.
A6: (−) Costi operativi (senza ammortamenti) | B6: 324 | C6: 346 | D6: 368 | E6: =E5*(1-Ipotesi!E7) -> 390.08 | F6: =F5*(1-Ipotesi!F7) -> 408.96231 | G6: =G5*(1-Ipotesi!G7) -> 426.70973 | H6: =H5*(1-Ipotesi!H7) -> 443.77812 | I6: =I5*(1-Ipotesi!I7) -> 457.09146 | K6: Ricavi × (1 − EBITDA margin) | L6: Materie prime, personale, servizi. Nello storico sono un dato; in previsione si ricavano dal margine ipotizzato (è un modo semplice: in un modello dettagliato ogni costo ha la sua ipotesi).
A7: EBITDA | B7: =B5-B6 -> 76 | C7: =C5-C6 -> 84 | D7: =D5-D6 -> 92 | E7: =E5-E6 -> 97.52 | F7: =F5-F6 -> 105.45569 | G7: =G5-G6 -> 113.42917 | H7: =H5-H6 -> 117.96634 | I7: =I5-I6 -> 121.50533 | K7: Ricavi − Costi operativi | L7: Margine operativo lordo: approssima la cassa generata dalla gestione prima di investimenti, circolante, interessi e imposte.
A8: (−) Ammortamenti | B8: 20 | C8: 21.5 | D8: 23 | E8: =E5*Ipotesi!E8 -> 24.38 | F8: =F5*Ipotesi!F8 -> 25.7209 | G8: =G5*Ipotesi!G8 -> 27.006945 | H8: =H5*Ipotesi!H8 -> 28.087223 | I8: =I5*Ipotesi!I8 -> 28.929839 | K8: Ricavi × % ammortamenti | L8: Quota di costo degli impianti attribuita all'anno. Non è un'uscita di cassa (la cassa è uscita quando l'impianto è stato comprato).
A9: EBIT (reddito operativo) | B9: =B7-B8 -> 56 | C9: =C7-C8 -> 62.5 | D9: =D7-D8 -> 69 | E9: =E7-E8 -> 73.14 | F9: =F7-F8 -> 79.73479 | G9: =G7-G8 -> 86.422224 | H9: =H7-H8 -> 89.879113 | I9: =I7-I8 -> 92.575486 | K9: EBITDA − Ammortamenti | L9: È il punto di partenza del FCFF. È un risultato PRIMA degli interessi, quindi appartiene a tutti i finanziatori (azionisti e creditori) e non dipende da quanto debito ha l'azienda.
A10: (−) Oneri finanziari | B10: 6.3 | C10: 5.9 | D10: 5.4 | E10: =Ipotesi!E14*SP!D13 -> 4.95 | F10: =Ipotesi!F14*SP!E13 -> 4.5 | G10: =Ipotesi!G14*SP!F13 -> 4.05 | H10: =Ipotesi!H14*SP!G13 -> 3.6 | I10: =Ipotesi!I14*SP!H13 -> 3.15 | K10: Tasso di interesse × Debito a inizio anno | L10: Calcolati sul debito di inizio anno per evitare un riferimento circolare (interessi → utile → cassa → debito → interessi).
A11: Utile ante imposte | B11: =B9-B10 -> 49.7 | C11: =C9-C10 -> 56.6 | D11: =D9-D10 -> 63.6 | E11: =E9-E10 -> 68.19 | F11: =F9-F10 -> 75.23479 | G11: =G9-G10 -> 82.372224 | H11: =H9-H10 -> 86.279113 | I11: =I9-I10 -> 89.425486 | K11: EBIT − Oneri finanziari | L11: Base imponibile (semplificata).
A12: (−) Imposte | B12: 13.9 | C12: 15.8 | D12: 17.8 | E12: =E11*Ipotesi!E10 -> 19.0932 | F12: =F11*Ipotesi!F10 -> 21.065741 | G12: =G11*Ipotesi!G10 -> 23.064223 | H12: =H11*Ipotesi!H10 -> 24.158152 | I12: =I11*Ipotesi!I10 -> 25.039136 | K12: Utile ante imposte × aliquota | L12: Imposte effettive: sono calcolate DOPO gli interessi, quindi beneficiano della loro deducibilità (scudo fiscale). Nel DCF useremo invece imposte calcolate sull'EBIT.
A13: Utile netto | B13: =B11-B12 -> 35.8 | C13: =C11-C12 -> 40.8 | D13: =D11-D12 -> 45.8 | E13: =E11-E12 -> 49.0968 | F13: =F11-F12 -> 54.169049 | G13: =G11-G12 -> 59.308001 | H13: =H11-H12 -> 62.120961 | I13: =I11-I12 -> 64.38635 | K13: Utile ante imposte − Imposte | L13: Risultato che spetta agli azionisti. Il DCF "unlevered" non parte da qui, ma l'utile serve per proiettare patrimonio netto, dividendi e cassa.

Sheet SP
A1: Stato patrimoniale (SP)
A2: Alfa S.p.A. — dati inventati, al 31 dicembre di ogni anno. Schema ridotto a sette voci.
B3: STORICO (dati di bilancio) | E3: PREVISIONE (piano a 5 anni)
A4: € milioni | B4: 2023A | C4: 2024A | D4: 2025A | E4: 2026E | F4: 2027E | G4: 2028E | H4: 2029E | I4: 2030E | K4: Formula (a parole) | L4: Spiegazione: cosa significa e perché si fa così
A5: ATTIVO
A6: Immobilizzazioni nette | B6: 200 | C6: 205 | D6: 211 | E6: =D6-RF!E9-CE!E8 -> 215.876 | F6: =E6-RF!F9-CE!F8 -> 221.02018 | G6: =F6-RF!G9-CE!G8 -> 223.72087 | H6: =G6-RF!H9-CE!H8 -> 226.5296 | I6: =H6-RF!I9-CE!I8 -> 229.42258 | K6: Immobilizzazioni(t−1) + Capex − Ammortamenti | L6: Gli impianti crescono con i nuovi investimenti e si riducono con gli ammortamenti. Nella formula il capex viene dal RF, dove ha segno negativo: per questo è sottratto.
A7: Crediti commerciali | B7: 66 | C7: 71 | D7: 76 | E7: =CE!E5*Ipotesi!E11/365 -> 80.153425 | F7: =CE!F5*Ipotesi!F11/365 -> 84.561863 | G7: =CE!G5*Ipotesi!G11/365 -> 88.789956 | H7: =CE!H5*Ipotesi!H11/365 -> 92.341554 | I7: =CE!I5*Ipotesi!I11/365 -> 95.111801 | K7: Ricavi × DSO / 365 | L7: Ricavi già fatturati ma non ancora incassati.
A8: Rimanenze | B8: 40 | C8: 43 | D8: 45 | E8: =CE!E6*Ipotesi!E12/365 -> 48.092055 | F8: =CE!F6*Ipotesi!F12/365 -> 50.420011 | G8: =CE!G6*Ipotesi!G12/365 -> 52.608049 | H8: =CE!H6*Ipotesi!H12/365 -> 54.712371 | I8: =CE!I6*Ipotesi!I12/365 -> 56.353742 | K8: Costi operativi × DIO / 365 | L8: Scorte di materie prime e prodotti: costi già sostenuti per beni non ancora venduti.
A9: Cassa | B9: 30 | C9: 35.8 | D9: 45.6 | E9: =RF!E16 -> 56.746464 | F9: =RF!F16 -> 70.988583 | G9: =RF!G16 -> 90.860173 | H9: =RF!H16 -> 112.9415 | I9: =RF!I16 -> 136.82195 | K9: Cassa finale del rendiconto finanziario | L9: In previsione la cassa NON è un'ipotesi: è il risultato del RF. È la voce che "chiude" il modello: se tutte le altre formule sono corrette, lo SP quadra da solo.
A10: Totale attivo | B10: =SUM(B6:B9) -> 336 | C10: =SUM(C6:C9) -> 354.8 | D10: =SUM(D6:D9) -> 377.6 | E10: =SUM(E6:E9) -> 400.86794 | F10: =SUM(F6:F9) -> 426.99064 | G10: =SUM(G6:G9) -> 455.97905 | H10: =SUM(H6:H9) -> 486.52502 | I10: =SUM(I6:I9) -> 517.71007 | K10: Somma delle voci dell'attivo
A11: PASSIVO E PATRIMONIO NETTO
A12: Debiti commerciali | B12: 62 | C12: 66 | D12: 71 | E12: =CE!E6*Ipotesi!E13/365 -> 74.809863 | F12: =CE!F6*Ipotesi!F13/365 -> 78.431128 | G12: =CE!G6*Ipotesi!G13/365 -> 81.834743 | H12: =CE!H6*Ipotesi!H13/365 -> 85.108133 | I12: =CE!I6*Ipotesi!I13/365 -> 87.661377 | K12: Costi operativi × DPO / 365 | L12: Acquisti già ricevuti ma non ancora pagati ai fornitori.
A13: Debito finanziario | B13: 130 | C13: 120 | D13: 110 | E13: =D13+RF!E11 -> 100 | F13: =E13+RF!F11 -> 90 | G13: =F13+RF!G11 -> 80 | H13: =G13+RF!H11 -> 70 | I13: =H13+RF!I11 -> 60 | K13: Debito(t−1) + Variazione del debito (dal RF) | L13: Prestiti bancari e obbligazioni. Scende ogni anno del rimborso ipotizzato.
A14: Patrimonio netto | B14: 144 | C14: 168.8 | D14: 196.6 | E14: =D14+CE!E13+RF!E12 -> 226.05808 | F14: =E14+CE!F13+RF!F12 -> 258.55951 | G14: =F14+CE!G13+RF!G12 -> 294.14431 | H14: =G14+CE!H13+RF!H12 -> 331.41689 | I14: =H14+CE!I13+RF!I12 -> 370.0487 | K14: PN(t−1) + Utile netto − Dividendi | L14: Cresce con l'utile non distribuito. I dividendi vengono dal RF con segno negativo, perciò sono sommati.
A15: Totale passivo e patrimonio netto | B15: =SUM(B12:B14) -> 336 | C15: =SUM(C12:C14) -> 354.8 | D15: =SUM(D12:D14) -> 377.6 | E15: =SUM(E12:E14) -> 400.86794 | F15: =SUM(F12:F14) -> 426.99064 | G15: =SUM(G12:G14) -> 455.97905 | H15: =SUM(H12:H14) -> 486.52502 | I15: =SUM(I12:I14) -> 517.71007 | K15: Somma delle voci del passivo e del PN
A16: Controllo quadratura (deve essere 0) | B16: =ROUND(B10-B15,6) -> 0 | C16: =ROUND(C10-C15,6) -> 0 | D16: =ROUND(D10-D15,6) -> 0 | E16: =ROUND(E10-E15,6) -> 0 | F16: =ROUND(F10-F15,6) -> 0 | G16: =ROUND(G10-G15,6) -> 0 | H16: =ROUND(H10-H15,6) -> 0 | I16: =ROUND(I10-I15,6) -> 0 | K16: Totale attivo − Totale passivo e PN | L16: Primo controllo di ogni modello a tre prospetti. Se non è zero, una voce è stata proiettata nello SP ma non nel RF (o viceversa).
A18: GRANDEZZE RICLASSIFICATE (servono per il DCF)
A19: Capitale circolante netto (CCN) | B19: =B7+B8-B12 -> 44 | C19: =C7+C8-C12 -> 48 | D19: =D7+D8-D12 -> 50 | E19: =E7+E8-E12 -> 53.435616 | F19: =F7+F8-F12 -> 56.550746 | G19: =G7+G8-G12 -> 59.563262 | H19: =H7+H8-H12 -> 61.945793 | I19: =I7+I8-I12 -> 63.804167 | K19: Crediti + Rimanenze − Debiti commerciali | L19: Cassa immobilizzata nel ciclo acquisti-produzione-vendita. Nel FCFF entra la sua VARIAZIONE annua, non il livello.
A20: Posizione finanziaria netta (PFN) | B20: =B13-B9 -> 100 | C20: =C13-C9 -> 84.2 | D20: =D13-D9 -> 64.4 | E20: =E13-E9 -> 43.253536 | F20: =F13-F9 -> 19.011417 | G20: =G13-G9 -> -10.860173 | H20: =H13-H9 -> -42.941497 | I20: =I13-I9 -> -76.82195 | K20: Debito finanziario − Cassa | L20: Debito netto. Quella al 31/12/2025 (data di valutazione) è il numero che si sottrae dall'Enterprise Value per arrivare all'Equity Value.
A21: Capitale investito netto (CIN) | B21: =B6+B19 -> 244 | C21: =C6+C19 -> 253 | D21: =D6+D19 -> 261 | E21: =E6+E19 -> 269.31162 | F21: =F6+F19 -> 277.57093 | G21: =G6+G19 -> 283.28414 | H21: =H6+H19 -> 288.47539 | I21: =I6+I19 -> 293.22675 | K21: Immobilizzazioni + CCN | L21: Quanto capitale serve per far funzionare l'attività operativa. Il DCF valuta proprio questo: l'Enterprise Value è il valore di mercato del CIN.
A22: Controllo: CIN − (PN + PFN) (deve essere 0) | B22: =ROUND(B21-(B14+B20),6) -> 0 | C22: =ROUND(C21-(C14+C20),6) -> 0 | D22: =ROUND(D21-(D14+D20),6) -> 0 | E22: =ROUND(E21-(E14+E20),6) -> 0 | F22: =ROUND(F21-(F14+F20),6) -> 0 | G22: =ROUND(G21-(G14+G20),6) -> 0 | H22: =ROUND(H21-(H14+H20),6) -> 0 | I22: =ROUND(I21-(I14+I20),6) -> 0 | K22: CIN = Patrimonio netto + PFN | L22: Lo stesso SP letto in due modi: dove è investito il capitale (CIN) e chi lo ha fornito (azionisti e creditori). È la versione contabile di EV = Equity + Debito netto.

Sheet RF
A1: Rendiconto finanziario (RF)
A2: Metodo indiretto: si parte dall'utile e si arriva alla variazione di cassa. Entrate positive, uscite negative (tra parentesi).
B3: STORICO (dati di bilancio) | E3: PREVISIONE (piano a 5 anni)
A4: € milioni | B4: 2023A | C4: 2024A | D4: 2025A | E4: 2026E | F4: 2027E | G4: 2028E | H4: 2029E | I4: 2030E | K4: Formula (a parole) | L4: Spiegazione: cosa significa e perché si fa così
A5: Utile netto | B5: n.d. | C5: =CE!C13 -> 40.8 | D5: =CE!D13 -> 45.8 | E5: =CE!E13 -> 49.0968 | F5: =CE!F13 -> 54.169049 | G5: =CE!G13 -> 59.308001 | H5: =CE!H13 -> 62.120961 | I5: =CE!I13 -> 64.38635 | K5: Dal CE | L5: Punto di partenza del metodo indiretto. Il 2023 non è calcolabile perché manca lo SP del 2022 (servono due SP consecutivi per fare un RF).
A6: (+) Ammortamenti | B6: n.d. | C6: =CE!C8 -> 21.5 | D6: =CE!D8 -> 23 | E6: =CE!E8 -> 24.38 | F6: =CE!F8 -> 25.7209 | G6: =CE!G8 -> 27.006945 | H6: =CE!H8 -> 28.087223 | I6: =CE!I8 -> 28.929839 | K6: Dal CE | L6: Costo che ha ridotto l'utile senza far uscire cassa: si riaggiunge.
A7: (−) Variazione del CCN | B7: n.d. | C7: =-(SP!C19-SP!B19) -> -4 | D7: =-(SP!D19-SP!C19) -> -2 | E7: =-(SP!E19-SP!D19) -> -3.4356164 | F7: =-(SP!F19-SP!E19) -> -3.1151295 | G7: =-(SP!G19-SP!F19) -> -3.0125164 | H7: =-(SP!H19-SP!G19) -> -2.3825305 | I7: =-(SP!I19-SP!H19) -> -1.8583738 | K7: −(CCN(t) − CCN(t−1)) | L7: Se il circolante aumenta, parte dell'utile è rimasta "incastrata" in crediti e magazzino invece di diventare cassa: segno meno.
A8: Flusso di cassa operativo | B8: n.d. | C8: =SUM(C5:C7) -> 58.3 | D8: =SUM(D5:D7) -> 66.8 | E8: =SUM(E5:E7) -> 70.041184 | F8: =SUM(F5:F7) -> 76.774819 | G8: =SUM(G5:G7) -> 83.30243 | H8: =SUM(H5:H7) -> 87.825654 | I8: =SUM(I5:I7) -> 91.457816 | K8: Utile netto + Ammortamenti − ΔCCN | L8: Cassa generata dalla gestione, DOPO interessi e imposte effettive.
A9: (−) Investimenti (Capex) | B9: n.d. | C9: =-(SP!C6-SP!B6+CE!C8) -> -26.5 | D9: =-(SP!D6-SP!C6+CE!D8) -> -29 | E9: =-CE!E5*Ipotesi!E9 -> -29.256 | F9: =-CE!F5*Ipotesi!F9 -> -30.86508 | G9: =-CE!G5*Ipotesi!G9 -> -29.70764 | H9: =-CE!H5*Ipotesi!H9 -> -30.895945 | I9: =-CE!I5*Ipotesi!I9 -> -31.822823 | K9: Storico: −(ΔImmobilizzazioni + Ammortamenti) Previsione: −Ricavi × % capex | L9: Nello storico il capex si ricava "al contrario" dallo SP: se le immobilizzazioni nette sono salite di 6 dopo 23 di ammortamenti, sono stati investiti 29.
A10: Flusso di cassa da investimenti | B10: n.d. | C10: =C9 -> -26.5 | D10: =D9 -> -29 | E10: =E9 -> -29.256 | F10: =F9 -> -30.86508 | G10: =G9 -> -29.70764 | H10: =H9 -> -30.895945 | I10: =I9 -> -31.822823 | K10: Pari al capex
A11: Variazione del debito finanziario | B11: n.d. | C11: =SP!C13-SP!B13 -> -10 | D11: =SP!D13-SP!C13 -> -10 | E11: =-Ipotesi!E15 -> -10 | F11: =-Ipotesi!F15 -> -10 | G11: =-Ipotesi!G15 -> -10 | H11: =-Ipotesi!H15 -> -10 | I11: =-Ipotesi!I15 -> -10 | K11: Storico: Debito(t) − Debito(t−1) Previsione: −Rimborso ipotizzato | L11: Negativa se si rimborsa debito, positiva se se ne accende di nuovo.
A12: (−) Dividendi | B12: n.d. | C12: =-(CE!C13-(SP!C14-SP!B14)) -> -16 | D12: =-(CE!D13-(SP!D14-SP!C14)) -> -18 | E12: =-CE!E13*Ipotesi!E16 -> -19.63872 | F12: =-CE!F13*Ipotesi!F16 -> -21.66762 | G12: =-CE!G13*Ipotesi!G16 -> -23.723201 | H12: =-CE!H13*Ipotesi!H16 -> -24.848385 | I12: =-CE!I13*Ipotesi!I16 -> -25.75454 | K12: Storico: −(Utile netto − ΔPN) Previsione: −Utile netto × payout | L12: Nello storico: la parte di utile che non è finita nel patrimonio netto è stata distribuita. In previsione, per semplicità, il dividendo è pagato nello stesso anno in cui l'utile è prodotto.
A13: Flusso di cassa da finanziamento | B13: n.d. | C13: =C11+C12 -> -26 | D13: =D11+D12 -> -28 | E13: =E11+E12 -> -29.63872 | F13: =F11+F12 -> -31.66762 | G13: =G11+G12 -> -33.723201 | H13: =H11+H12 -> -34.848385 | I13: =I11+I12 -> -35.75454 | K13: ΔDebito + Dividendi | L13: Rapporti con chi finanzia l'azienda: creditori e azionisti.
A14: Variazione di cassa | B14: n.d. | C14: =C8+C10+C13 -> 5.8 | D14: =D8+D10+D13 -> 9.8 | E14: =E8+E10+E13 -> 11.146464 | F14: =F8+F10+F13 -> 14.24212 | G14: =G8+G10+G13 -> 19.87159 | H14: =H8+H10+H13 -> 22.081324 | I14: =I8+I10+I13 -> 23.880452 | K14: Operativo + Investimenti + Finanziamento
A15: Cassa iniziale | B15: n.d. | C15: =SP!B9 -> 30 | D15: =SP!C9 -> 35.8 | E15: =SP!D9 -> 45.6 | F15: =SP!E9 -> 56.746464 | G15: =SP!F9 -> 70.988583 | H15: =SP!G9 -> 90.860173 | I15: =SP!H9 -> 112.9415 | K15: Cassa dello SP dell'anno precedente
A16: Cassa finale | B16: n.d. | C16: =C15+C14 -> 35.8 | D16: =D15+D14 -> 45.6 | E16: =E15+E14 -> 56.746464 | F16: =F15+F14 -> 70.988583 | G16: =G15+G14 -> 90.860173 | H16: =H15+H14 -> 112.9415 | I16: =I15+I14 -> 136.82195 | K16: Cassa iniziale + Variazione di cassa | L16: In previsione questo numero va nello SP: è il collegamento che fa quadrare i tre prospetti.
A17: Controllo: Cassa finale − Cassa SP (deve essere 0) | B17: n.d. | C17: =ROUND(C16-SP!C9,6) -> 0 | D17: =ROUND(D16-SP!D9,6) -> 0 | E17: =ROUND(E16-SP!E9,6) -> 0 | F17: =ROUND(F16-SP!F9,6) -> 0 | G17: =ROUND(G16-SP!G9,6) -> 0 | H17: =ROUND(H16-SP!H9,6) -> 0 | I17: =ROUND(I16-SP!I9,6) -> 0 | K17: Cassa finale RF − Cassa SP | L17: Nello storico è una vera verifica: il RF ricostruito deve arrivare alla cassa di bilancio. In previsione è zero per costruzione.

Sheet WACC
A1: Costo medio ponderato del capitale (WACC)
A2: Il tasso di sconto dei FCFF: quanto rendimento chiedono, in media, azionisti e creditori per finanziare l'azienda.
A4: Voce | B4: Valore | D4: Formula (a parole) | E4: Spiegazione
A5: 1. Costo dell'equity (Ke) con il CAPM
A6: Tasso privo di rischio (Rf) | B6: =Ipotesi!B25 -> 0.035 | D6: Dal foglio Ipotesi | E6: Rendimento minimo che si ottiene senza correre rischi: è la base di qualunque tasso di sconto.
A7: Premio per il rischio di mercato (ERP) | B7: =Ipotesi!B26 -> 0.055 | D7: Dal foglio Ipotesi | E7: Rendimento atteso del mercato azionario in eccesso rispetto a Rf.
A8: Beta unlevered (βu) | B8: =Ipotesi!B27 -> 0.9 | D8: Dal foglio Ipotesi | E8: Rischio del solo business, senza l'effetto del debito.
A9: Aliquota fiscale (t) | B9: =Ipotesi!I10 -> 0.28 | D9: Dal foglio Ipotesi (aliquota di lungo periodo, 2030E) | E9: Gli interessi sono deducibili: lo Stato "paga" una parte del costo del debito.
A10: Rapporto D / E obiettivo | B10: =B20/B21 -> 0.17647059 | D10: Peso debito / Peso equity | E10: Leva finanziaria obiettivo: quanti euro di debito per ogni euro di equity (a valori di mercato).
A11: Beta levered (βL) | B11: =B8*(1+(1-B9)*B10) -> 1.0143529 | D11: βu × [1 + (1 − t) × D/E] | E11: Formula di Hamada. Il debito rende l'utile per gli azionisti più volatile: a parità di business, più leva = beta più alto. Il termine (1 − t) riflette lo scudo fiscale, che attenua l'effetto.
A12: Costo dell'equity (Ke) | B12: =B6+B11*B7 -> 0.090789412 | D12: Rf + βL × ERP | E12: CAPM: gli azionisti chiedono il tasso privo di rischio più un premio proporzionale al rischio sistematico (non diversificabile) del titolo, misurato dal beta.
A14: 2. Costo del debito (Kd)
A15: Costo del debito lordo (Kd) | B15: =Ipotesi!B29 -> 0.045 | D15: Dal foglio Ipotesi | E15: Rendimento chiesto dai creditori.
A16: Costo del debito dopo le imposte | B16: =B15*(1-B9) -> 0.0324 | D16: Kd × (1 − t) | E16: Ogni euro di interessi riduce le imposte di t euro: il costo effettivo è più basso. È QUI che lo scudo fiscale entra nel DCF, ed è il motivo per cui nel FCFF le imposte si calcolano sull'EBIT senza togliere gli interessi.
A18: 3. Struttura finanziaria obiettivo (pesi a valori di mercato)
A19: I pesi vanno a valori di mercato, non contabili: l'equity a bilancio (PN) sottostima quasi sempre il valore di mercato.
A20: Peso del debito D / (D + E) | B20: =Ipotesi!B28 -> 0.15 | D20: Dal foglio Ipotesi | E20: Quota di debito nella struttura obiettivo.
A21: Peso dell'equity E / (D + E) | B21: =1-B20 -> 0.85 | D21: 1 − Peso del debito | E21: I due pesi sommano a 100%.
A23: 4. WACC
A24: WACC | B24: =B21*B12+B20*B16 -> 0.082031 | D24: E/(D+E) × Ke + D/(D+E) × Kd × (1 − t) | E24: Media dei due costi, pesata per quanto ciascuna fonte finanzia l'azienda. Il debito costa meno dell'equity (i creditori sono pagati prima e gli interessi sono deducibili), ma aumentare la leva fa salire sia il beta sia, oltre un certo punto, il costo del debito: il WACC non scende all'infinito.
A26: Per confronto
A27: Leva effettiva al 31/12/2025: PFN / EV | B27: =SP!D20/DCF!B33 -> 0.071633654 | D27: PFN 2025 / Enterprise Value stimato | E27: Controllo di coerenza. Oggi la leva effettiva è più bassa dell'obiettivo e nel piano il debito scende ancora: usare il peso obiettivo significa ipotizzare che nel lungo periodo l'azienda torni a una leva "normale" per il settore. È una scelta frequente, ma è un'ipotesi e va dichiarata.

Sheet DCF
A1: Valutazione DCF
A2: Dal flusso di cassa al valore per azione, in cinque passi. Entrate positive, uscite negative (tra parentesi).
B3: STORICO (dati di bilancio) | E3: PREVISIONE (piano a 5 anni)
A4: € milioni | B4: 2023A | C4: 2024A | D4: 2025A | E4: 2026E | F4: 2027E | G4: 2028E | H4: 2029E | I4: 2030E | K4: Formula (a parole) | L4: Spiegazione: cosa significa e perché si fa così
A5: PASSO 1 — Free Cash Flow to the Firm (FCFF)
A6: EBIT | B6: n.d. | C6: =CE!C9 -> 62.5 | D6: =CE!D9 -> 69 | E6: =CE!E9 -> 73.14 | F6: =CE!F9 -> 79.73479 | G6: =CE!G9 -> 86.422224 | H6: =CE!H9 -> 89.879113 | I6: =CE!I9 -> 92.575486 | K6: Dal CE | L6: Si parte dall'EBIT e non dall'utile netto: il FCFF è la cassa disponibile per TUTTI i finanziatori, quindi si misura prima degli interessi.
A7: (−) Imposte figurative sull'EBIT | B7: n.d. | C7: =-C6*Ipotesi!C10 -> -17.446996 | D7: =-D6*Ipotesi!D10 -> -19.311321 | E7: =-E6*Ipotesi!E10 -> -20.4792 | F7: =-F6*Ipotesi!F10 -> -22.325741 | G7: =-G6*Ipotesi!G10 -> -24.198223 | H7: =-H6*Ipotesi!H10 -> -25.166152 | I7: =-I6*Ipotesi!I10 -> -25.921136 | K7: −EBIT × aliquota | L7: Imposte che l'azienda pagherebbe se non avesse debito. Sono più alte di quelle del CE perché ignorano la deducibilità degli interessi. Quel risparmio non va perso: è già nel WACC, tramite Kd × (1 − t). Contarlo anche qui sarebbe un doppio conteggio.
A8: NOPAT (utile operativo dopo le imposte) | B8: n.d. | C8: =C6+C7 -> 45.053004 | D8: =D6+D7 -> 49.688679 | E8: =E6+E7 -> 52.6608 | F8: =F6+F7 -> 57.409049 | G8: =G6+G7 -> 62.224001 | H8: =H6+H7 -> 64.712961 | I8: =I6+I7 -> 66.65435 | K8: EBIT × (1 − t) | L8: Net Operating Profit After Taxes: l'utile che l'azienda farebbe se fosse finanziata solo con equity.
A9: (+) Ammortamenti | B9: n.d. | C9: =CE!C8 -> 21.5 | D9: =CE!D8 -> 23 | E9: =CE!E8 -> 24.38 | F9: =CE!F8 -> 25.7209 | G9: =CE!G8 -> 27.006945 | H9: =CE!H8 -> 28.087223 | I9: =CE!I8 -> 28.929839 | K9: Dal CE | L9: Costo non monetario: ha ridotto l'EBIT (e le imposte) ma non è uscita cassa. Si riaggiunge.
A10: (−) Investimenti (Capex) | B10: n.d. | C10: =RF!C9 -> -26.5 | D10: =RF!D9 -> -29 | E10: =RF!E9 -> -29.256 | F10: =RF!F9 -> -30.86508 | G10: =RF!G9 -> -29.70764 | H10: =RF!H9 -> -30.895945 | I10: =RF!I9 -> -31.822823 | K10: Dal RF | L10: Cassa spesa per mantenere e far crescere la capacità produttiva.
A11: (−) Variazione del CCN | B11: n.d. | C11: =RF!C7 -> -4 | D11: =RF!D7 -> -2 | E11: =RF!E7 -> -3.4356164 | F11: =RF!F7 -> -3.1151295 | G11: =RF!G7 -> -3.0125164 | H11: =RF!H7 -> -2.3825305 | I11: =RF!I7 -> -1.8583738 | K11: Dal RF | L11: Cassa assorbita dall'aumento di crediti e magazzino, al netto dei debiti verso fornitori.
A12: FCFF | B12: n.d. | C12: =SUM(C8:C11) -> 36.053004 | D12: =SUM(D8:D11) -> 41.688679 | E12: =SUM(E8:E11) -> 44.349184 | F12: =SUM(F8:F11) -> 49.149739 | G12: =SUM(G8:G11) -> 56.51079 | H12: =SUM(H8:H11) -> 59.521709 | I12: =SUM(I8:I11) -> 61.902992 | K12: NOPAT + Ammortamenti − Capex − ΔCCN | L12: Cassa prodotta dall'attività operativa dopo imposte e investimenti, prima di qualunque pagamento a creditori (interessi, rimborsi) e azionisti (dividendi). È il flusso che si attualizza al WACC.
A13: Controllo: riconciliazione con il RF (deve essere 0) | B13: n.d. | C13: =ROUND(RF!C8+CE!C10*(1-Ipotesi!C10)+RF!C9-C12,6) -> 0 | D13: =ROUND(RF!D8+CE!D10*(1-Ipotesi!D10)+RF!D9-D12,6) -> 0 | E13: =ROUND(RF!E8+CE!E10*(1-Ipotesi!E10)+RF!E9-E12,6) -> 0 | F13: =ROUND(RF!F8+CE!F10*(1-Ipotesi!F10)+RF!F9-F12,6) -> 0 | G13: =ROUND(RF!G8+CE!G10*(1-Ipotesi!G10)+RF!G9-G12,6) -> 0 | H13: =ROUND(RF!H8+CE!H10*(1-Ipotesi!H10)+RF!H9-H12,6) -> 0 | I13: =ROUND(RF!I8+CE!I10*(1-Ipotesi!I10)+RF!I9-I12,6) -> 0 | K13: Flusso operativo (RF) + Oneri finanziari × (1 − t) + Capex − FCFF | L13: Il FCFF si può ottenere anche dal rendiconto finanziario: al flusso operativo si riaggiungono gli interessi al netto dello scudo fiscale e si toglie il capex. Le due strade devono dare lo stesso numero.
A15: PASSO 2 — Attualizzazione dei flussi espliciti
A16: Periodo t (anni dalla data di valutazione) | E16: 1 | F16: =E16+1 -> 2 | G16: =F16+1 -> 3 | H16: =G16+1 -> 4 | I16: =H16+1 -> 5 | K16: 1, 2, 3, 4, 5 | L16: Distanza in anni tra il 31/12/2025 e il momento in cui si ipotizza arrivi il flusso (fine anno).
A17: WACC | E17: =WACC!$B$24 -> 0.082031 | F17: =WACC!$B$24 -> 0.082031 | G17: =WACC!$B$24 -> 0.082031 | H17: =WACC!$B$24 -> 0.082031 | I17: =WACC!$B$24 -> 0.082031 | K17: Dal foglio WACC | L17: Lo stesso tasso per tutti gli anni: si assume struttura finanziaria e rischio costanti.
A18: Fattore di sconto | E18: =1/(1+E17)^E16 -> 0.92418794 | F18: =1/(1+F17)^F16 -> 0.85412335 | G18: =1/(1+G17)^G16 -> 0.7893705 | H18: =1/(1+H17)^H16 -> 0.72952669 | I18: =1/(1+I17)^I16 -> 0.67421977 | K18: 1 / (1 + WACC)^t | L18: Quanto vale oggi 1 euro incassato tra t anni. Più lontano è il flusso (o più alto il WACC), meno vale. Convenzione di fine anno; con la mid-year convention l'esponente sarebbe t − 0,5.
A19: Valore attuale del FCFF | E19: =E12*E18 -> 40.986981 | F19: =F12*F18 -> 41.97994 | G19: =G12*G18 -> 44.607951 | H19: =H12*H18 -> 43.422675 | I19: =I12*I18 -> 41.736221 | K19: FCFF × Fattore di sconto | L19: Ogni flusso riportato al 31/12/2025.
A21: PASSO 3 — Terminal Value (TV) | B21: Valore
A22: Crescita perpetua (g) | B22: =Ipotesi!B20 -> 0.02 | K22: Dal foglio Ipotesi | L22: Tasso a cui i flussi crescono per sempre dopo il 2030.
A23: WACC | B23: =WACC!B24 -> 0.082031 | K23: Dal foglio WACC
A24: FCFF dell'ultimo anno di piano (2030E) | B24: =I12 -> 61.902992 | K24: FCFF 2030E | L24: L'ultimo flusso esplicito. Deve rappresentare un anno "a regime": margini sostenibili, capex coerente con la crescita g.
A25: FCFF del primo anno oltre il piano (2031) | B25: =B24*(1+B22) -> 63.141052 | K25: FCFF 2030E × (1 + g) | L25: La formula di Gordon vuole al numeratore il flusso dell'anno SUCCESSIVO. Dimenticare (1 + g) è l'errore più frequente.
A26: Terminal Value al 31/12/2030 | B26: =B25/(B23-B22) -> 1017.8951 | K26: FCFF 2031 / (WACC − g) | L26: Valore, visto dal 2030, di tutti i flussi dal 2031 all'infinito. È una rendita perpetua crescente: la somma FCFF×(1+g)/(1+WACC) + FCFF×(1+g)²/(1+WACC)² + … è una serie geometrica che converge a questa formula solo se g < WACC.
A27: Fattore di sconto dell'anno 2030 | B27: =I18 -> 0.67421977 | K27: 1 / (1 + WACC)^5 | L27: Il TV è un valore al 2030, non a oggi: va scontato con il fattore dell'ultimo anno di piano (t = 5, non 6).
A28: Valore attuale del Terminal Value | B28: =B26*B27 -> 686.28501 | K28: TV × Fattore di sconto 2030
A30: PASSO 4 — Da Enterprise Value a valore per azione | B30: Valore
A31: Somma dei valori attuali dei FCFF 2026E-2030E | B31: =SUM(E19:I19) -> 212.73377 | K31: Σ Valore attuale FCFF | L31: Valore creato nei cinque anni di piano.
A32: (+) Valore attuale del Terminal Value | B32: =B28 -> 686.28501 | K32: Dal passo 3 | L32: Valore creato dal 2031 in poi.
A33: Enterprise Value (EV) | B33: =B31+B32 -> 899.01878 | K33: Σ VA FCFF + VA TV | L33: Valore dell'attività operativa, indipendente da come è finanziata. Appartiene a tutti i finanziatori.
A34: (−) Posizione finanziaria netta al 31/12/2025 | B34: =-SP!D20 -> -64.4 | K34: −(Debito finanziario − Cassa) | L34: Si toglie ciò che spetta ai creditori (al netto della cassa disponibile). Va presa alla data di valutazione, non a fine piano.
A35: Equity Value | B35: =B33+B34 -> 834.61878 | K35: EV − PFN | L35: Valore che resta agli azionisti.
A36: Numero di azioni (milioni) | B36: =Ipotesi!B21 -> 50 | K36: Dal foglio Ipotesi
A37: Valore per azione (€) | B37: =B35/B36 -> 16.692376 | K37: Equity Value / Numero di azioni | L37: Il risultato finale del DCF.
A38: Prezzo di mercato (€) | B38: =Ipotesi!B22 -> 14.5 | K38: Dal foglio Ipotesi
A39: Scostamento dal prezzo di mercato | B39: =B37/B38-1 -> 0.15119832 | K39: Valore per azione / Prezzo − 1 | L39: Positivo: secondo il modello l'azione è sottovalutata. Ma prima di concluderlo va capito PERCHÉ il mercato la pensa diversamente: quale ipotesi sta scontando?
A41: PASSO 5 — Controlli di ragionevolezza | B41: Valore
A42: Peso del Terminal Value sull'EV | B42: =B32/B33 -> 0.76337116 | K42: VA TV / EV | L42: Di solito tra 60% e 80%. Più è alto, più il valore dipende da WACC e g (cioè da due numeri stimati) e meno dal piano.
A43: EV / EBITDA 2025A | B43: =B33/CE!D7 -> 9.7719433 | K43: EV / EBITDA dell'ultimo anno chiuso | L43: Multiplo implicito nella valutazione: va confrontato con quello delle società comparabili quotate.
A44: EV / EBITDA 2026E | B44: =B33/CE!E7 -> 9.2188144 | K44: EV / EBITDA del primo anno di piano
...

Sheet Sensitività
A1: Analisi di sensitività
A2: Valore per azione (€) al variare di WACC (righe) e crescita perpetua g (colonne). La cella centrale è il caso base.
A4: Passo WACC | B4: 0.005 | C4: Passo g | D4: 0.005
B6: Crescita perpetua (g) | H6: Spiegazione
A7: WACC ↓ | B7: =DCF!$B$22+(0-2)*$D$4 -> 0.01 | C7: =DCF!$B$22+(1-2)*$D$4 -> 0.015 | D7: =DCF!$B$22+(2-2)*$D$4 -> 0.02 | E7: =DCF!$B$22+(3-2)*$D$4 -> 0.025 | F7: =DCF!$B$22+(4-2)*$D$4 -> 0.03 | H7: Come si legge: Ogni cella ricalcola tutto il DCF con una coppia diversa di WACC e g, lasciando invariati i FCFF. Muoversi a destra (g più alto) o in alto (WACC più basso) fa salire il valore.
A8: =DCF!$B$23+(0-2)*$B$4 -> 0.072031 | B8: =(SUMPRODUCT(DCF!$E$12:$I$12/(1+$A8)^DCF!$E$16:$I$16)+DCF!$I$12*(1+B$7)/($A8-B$7)/(1+$A8)^DCF!$I$16+DCF!$B$34)/DCF!$B$36 -> 17.324752 | C8: =(SUMPRODUCT(DCF!$E$12:$I$12/(1+$A8)^DCF!$E$16:$I$16)+DCF!$I$12*(1+C$7)/($A8-C$7)/(1+$A8)^DCF!$I$16+DCF!$B$34)/DCF!$B$36 -> 18.649589 | D8: =(SUMPRODUCT(DCF!$E$12:$I$12/(1+$A8)^DCF!$E$16:$I$16)+DCF!$I$12*(1+D$7)/($A8-D$7)/(1+$A8)^DCF!$I$16+DCF!$B$34)/DCF!$B$36 -> 20.229051 | E8: =(SUMPRODUCT(DCF!$E$12:$I$12/(1+$A8)^DCF!$E$16:$I$16)+DCF!$I$12*(1+E$7)/($A8-E$7)/(1+$A8)^DCF!$I$16+DCF!$B$34)/DCF!$B$36 -> 22.144347 | F8: =(SUMPRODUCT(DCF!$E$12:$I$12/(1+$A8)^DCF!$E$16:$I$16)+DCF!$I$12*(1+F$7)/($A8-F$7)/(1+$A8)^DCF!$I$16+DCF!$B$34)/DCF!$B$36 -> 24.515329 | H8: Cosa c'è nella formula: Valore per azione = [ Σ FCFF(t) / (1 + WACC)^t + FCFF(2030) × (1 + g) / (WACC − g) / (1 + WACC)^5 − PFN ] / n. azioni. Il primo pezzo è un MATR.SOMMA.PRODOTTO (SUMPRODUCT) che sconta i cinque flussi in una sola cella.
A9: =DCF!$B$23+(1-2)*$B$4 -> 0.077031 | B9: =(SUMPRODUCT(DCF!$E$12:$I$12/(1+$A9)^DCF!$E$16:$I$16)+DCF!$I$12*(1+B$7)/($A9-B$7)/(1+$A9)^DCF!$I$16+DCF!$B$34)/DCF!$B$36 -> 15.898581 | C9: =(SUMPRODUCT(DCF!$E$12:$I$12/(1+$A9)^DCF!$E$16:$I$16)+DCF!$I$12*(1+C$7)/($A9-C$7)/(1+$A9)^DCF!$I$16+DCF!$B$34)/DCF!$B$36 -> 17.004987 | D9: =(SUMPRODUCT(DCF!$E$12:$I$12/(1+$A9)^DCF!$E$16:$I$16)+DCF!$I$12*(1+D$7)/($A9-D$7)/(1+$A9)^DCF!$I$16+DCF!$B$34)/DCF!$B$36 -> 18.305393 | E9: =(SUMPRODUCT(DCF!$E$12:$I$12/(1+$A9)^DCF!$E$16:$I$16)+DCF!$I$12*(1+E$7)/($A9-E$7)/(1+$A9)^DCF!$I$16+DCF!$B$34)/DCF!$B$36 -> 19.855728 | F9: =(SUMPRODUCT(DCF!$E$12:$I$12/(1+$A9)^DCF!$E$16:$I$16)+DCF!$I$12*(1+F$7)/($A9-F$7)/(1+$A9)^DCF!$I$16+DCF!$B$34)/DCF!$B$36 -> 21.735705 | H9: Perché serve: Il DCF non produce un numero, produce un intervallo. WACC e g sono stime: ±0,5% su ciascuno è un'incertezza del tutto normale. La tabella mostra quanto il risultato regge a errori plausibili.
A10: =DCF!$B$23+(2-2)*$B$4 -> 0.082031 | B10: =(SUMPRODUCT(DCF!$E$12:$I$12/(1+$A10)^DCF!$E$16:$I$16)+DCF!$I$12*(1+B$7)/($A10-B$7)/(1+$A10)^DCF!$I$16+DCF!$B$34)/DCF!$B$36 -> 14.670965 | C10: =(SUMPRODUCT(DCF!$E$12:$I$12/(1+$A10)^DCF!$E$16:$I$16)+DCF!$I$12*(1+C$7)/($A10-C$7)/(1+$A10)^DCF!$I$16+DCF!$B$34)/DCF!$B$36 -> 15.606279 | D10: =(SUMPRODUCT(DCF!$E$12:$I$12/(1+$A10)^DCF!$E$16:$I$16)+DCF!$I$12*(1+D$7)/($A10-D$7)/(1+$A10)^DCF!$I$16+DCF!$B$34)/DCF!$B$36 -> 16.692376 | E10: =(SUMPRODUCT(DCF!$E$12:$I$12/(1+$A10)^DCF!$E$16:$I$16)+DCF!$I$12*(1+E$7)/($A10-E$7)/(1+$A10)^DCF!$I$16+DCF!$B$34)/DCF!$B$36 -> 17.968912 | F10: =(SUMPRODUCT(DCF!$E$12:$I$12/(1+$A10)^DCF!$E$16:$I$16)+DCF!$I$12*(1+F$7)/($A10-F$7)/(1+$A10)^DCF!$I$16+DCF!$B$34)/DCF!$B$36 -> 19.490789 | H10: Cosa osservare: L'effetto non è simmetrico né lineare: quando WACC − g diventa piccolo (angolo in alto a destra) il valore accelera, perché il denominatore del Terminal Value si avvicina a zero.
A11: =DCF!$B$23+(3-2)*$B$4 -> 0.087031 | B11: =(SUMPRODUCT(DCF!$E$12:$I$12/(1+$A11)^DCF!$E$16:$I$16)+DCF!$I$12*(1+B$7)/($A11-B$7)/(1+$A11)^DCF!$I$16+DCF!$B$34)/DCF!$B$36 -> 13.603228 | C11: =(SUMPRODUCT(DCF!$E$12:$I$12/(1+$A11)^DCF!$E$16:$I$16)+DCF!$I$12*(1+C$7)/($A11-C$7)/(1+$A11)^DCF!$I$16+DCF!$B$34)/DCF!$B$36 -> 14.40225 | D11: =(SUMPRODUCT(DCF!$E$12:$I$12/(1+$A11)^DCF!$E$16:$I$16)+DCF!$I$12*(1+D$7)/($A11-D$7)/(1+$A11)^DCF!$I$16+DCF!$B$34)/DCF!$B$36 -> 15.320474 | E11: =(SUMPRODUCT(DCF!$E$12:$I$12/(1+$A11)^DCF!$E$16:$I$16)+DCF!$I$12*(1+E$7)/($A11-E$7)/(1+$A11)^DCF!$I$16+DCF!$B$34)/DCF!$B$36 -> 16.386725 | F11: =(SUMPRODUCT(DCF!$E$12:$I$12/(1+$A11)^DCF!$E$16:$I$16)+DCF!$I$12*(1+F$7)/($A11-F$7)/(1+$A11)^DCF!$I$16+DCF!$B$34)/DCF!$B$36 -> 17.639936 | H11: Alternativa in Excel: Lo stesso risultato si ottiene con Dati → Analisi di simulazione → Tabella dati, che ricalcola il modello senza scrivere la formula. Qui è scritta per esteso perché si veda cosa succede.
A12: =DCF!$B$23+(4-2)*$B$4 -> 0.092031 | B12: =(SUMPRODUCT(DCF!$E$12:$I$12/(1+$A12)^DCF!$E$16:$I$16)+DCF!$I$12*(1+B$7)/($A12-B$7)/(1+$A12)^DCF!$I$16+DCF!$B$34)/DCF!$B$36 -> 12.666124 | C12: =(SUMPRODUCT(DCF!$E$12:$I$12/(1+$A12)^DCF!$E$16:$I$16)+DCF!$I$12*(1+C$7)/($A12-C$7)/(1+$A12)^DCF!$I$16+DCF!$B$34)/DCF!$B$36 -> 13.35498 | D12: =(SUMPRODUCT(DCF!$E$12:$I$12/(1+$A12)^DCF!$E$16:$I$16)+DCF!$I$12*(1+D$7)/($A12-D$7)/(1+$A12)^DCF!$I$16+DCF!$B$34)/DCF!$B$36 -> 14.139469 | E12: =(SUMPRODUCT(DCF!$E$12:$I$12/(1+$A12)^DCF!$E$16:$I$16)+DCF!$I$12*(1+E$7)/($A12-E$7)/(1+$A12)^DCF!$I$16+DCF!$B$34)/DCF!$B$36 -> 15.040992 | F12: =(SUMPRODUCT(DCF!$E$12:$I$12/(1+$A12)^DCF!$E$16:$I$16)+DCF!$I$12*(1+F$7)/($A12-F$7)/(1+$A12)^DCF!$I$16+DCF!$B$34)/DCF!$B$36 -> 16.087848 | H12: Limite: Si muovono solo due ipotesi finanziarie. Le ipotesi operative (crescita, margini, capex) contano altrettanto: provale a mano dal foglio Ipotesi.
A14: Controllo: cella centrale − valore per azione del foglio DCF (deve essere 0) | F14: =ROUND(D10-DCF!B37,6) -> 0
A16: Prezzo di mercato (€) | B16: =Ipotesi!B22 -> 14.5 | C16: Le celle in rosso sono sotto il prezzo di mercato.
