Workbook

Sheet Stato Patrimoniale
A1: FIDIA FARMACEUTICI S.p.A. — Balance Sheet
A2: Stato Patrimoniale Consolidato — valori in migliaia di Euro, salvo diversa indicazione | V2: Tabella di supporto ai grafici
V3: Anno | W3: Totale Attivo | X3: Patrimonio Netto
A4: 1. STATO PATRIMONIALE CONSOLIDATO IFRS | V4: 2021 | W4: =B131 -> 575976 | X4: =B133 -> 212041
A5: Voce | B5: Nota | C5: 31/12/2025 | D5: 31/12/2024 | E5: Variazione | F5: Var % | V5: 2022 | W5: =C131 -> 640290 | X5: =C133 -> 255622
A6: ATTIVO | V6: 2023 | W6: =D131 -> 655310 | X6: =D133 -> 291845
A7: Attività non correnti | V7: 2024 | W7: =E131 -> 797546 | X7: =E133 -> 329380
A8: Immobili, impianti e macchinari | B8: 4.1 | C8: 133751 | D8: 124113 | E8: =C8-D8 -> 9638 | F8: =IFERROR(E8/ABS(D8),"n.s.") -> 0.07765504 | V8: 2025 | W8: =F131 -> 841669 | X8: =F133 -> 362731
A9: Attività immateriali | B9: 4.2 | C9: 230170 | D9: 229289 | E9: =C9-D9 -> 881 | F9: =IFERROR(E9/ABS(D9),"n.s.") -> 0.0038423125
A10: Avviamenti | B10: 4.3 | C10: 113611 | D10: 110080 | E10: =C10-D10 -> 3531 | F10: =IFERROR(E10/ABS(D10),"n.s.") -> 0.032076672 | V10: Tabella di supporto ai grafici
A11: Partecipazioni | B11: 4.4 | C11: 38671 | D11: 24 | E11: =C11-D11 -> 38647 | F11: =IFERROR(E11/ABS(D11),"n.s.") -> 1610.2917 | V11: Anno | W11: Debiti a breve | X11: Debiti a m/l | Y11: Patrimonio Netto
A12: Altre partecipazioni e titoli | B12: 4.4 | C12: 89 | D12: 89 | E12: =C12-D12 -> 0 | F12: =IFERROR(E12/ABS(D12),"n.s.") -> 0 | V12: 2024 | W12: =D96 -> 247514 | X12: =D105 -> 220650 | Y12: =D108 -> 329380
A13: Crediti | B13: 4.5 | C13: 1064 | D13: 1374 | E13: =C13-D13 -> -310 | F13: =IFERROR(E13/ABS(D13),"n.s.") -> -0.22561863 | V13: 2025 | W13: =C96 -> 187427 | X13: =C105 -> 291510 | Y13: =C108 -> 362731
A14: Attività fiscali differite | B14: 4.6 | C14: 26035 | D14: 20366 | E14: =C14-D14 -> 5669 | F14: =IFERROR(E14/ABS(D14),"n.s.") -> 0.27835608
A15: Totale attività non correnti | C15: =SUM(C8:C14) -> 543391 | D15: =SUM(D8:D14) -> 485335 | E15: =C15-D15 -> 58056 | F15: =IFERROR(E15/ABS(D15),"n.s.") -> 0.11962047
A17: Attività correnti
A18: Rimanenze di magazzino | B18: 4.7 | C18: 88484 | D18: 89686 | E18: =C18-D18 -> -1202 | F18: =IFERROR(E18/ABS(D18),"n.s.") -> -0.013402315
A19: Crediti commerciali | B19: 4.8 | C19: 141729 | D19: 148997 | E19: =C19-D19 -> -7268 | F19: =IFERROR(E19/ABS(D19),"n.s.") -> -0.048779506
A20: Crediti tributari | B20: 4.9 | C20: 15581 | D20: 5624 | E20: =C20-D20 -> 9957 | F20: =IFERROR(E20/ABS(D20),"n.s.") -> 1.7704481
A21: Altre attività correnti | B21: 4.10 | C21: 15281 | D21: 19087 | E21: =C21-D21 -> -3806 | F21: =IFERROR(E21/ABS(D21),"n.s.") -> -0.19940273
A22: Strumenti derivati valutati al fair value | B22: 4.11 | C22: 188 | D22: 1162 | E22: =C22-D22 -> -974 | F22: =IFERROR(E22/ABS(D22),"n.s.") -> -0.83820998
A23: Investimenti finanziari a breve termine e disponibilità liquide | B23: 4.12 | C23: 37015 | D23: 47655 | E23: =C23-D23 -> -10640 | F23: =IFERROR(E23/ABS(D23),"n.s.") -> -0.22327143
A24: Totale attività correnti | C24: =SUM(C18:C23) -> 298278 | D24: =SUM(D18:D23) -> 312211 | E24: =C24-D24 -> -13933 | F24: =IFERROR(E24/ABS(D24),"n.s.") -> -0.044626871
A26: TOTALE ATTIVO | C26: =C15+C24 -> 841669 | D26: =D15+D24 -> 797546 | E26: =C26-D26 -> 44123 | F26: =IFERROR(E26/ABS(D26),"n.s.") -> 0.055323455
A28: PASSIVO E PATRIMONIO NETTO
A29: Patrimonio netto
A30: Capitale sociale | C30: 36120 | D30: 36120 | E30: =C30-D30 -> 0 | F30: =IFERROR(E30/ABS(D30),"n.s.") -> 0
A31: Riserva sovrapprezzo azioni | C31: 0 | D31: 0 | E31: =C31-D31 -> 0 | F31: =IFERROR(E31/ABS(D31),"n.s.") -> n.s.
A32: Azioni proprie | C32: 0 | D32: 0 | E32: =C32-D32 -> 0 | F32: =IFERROR(E32/ABS(D32),"n.s.") -> n.s.
A33: Riserva azioni società controllante | C33: 38648 | D33: 0 | E33: =C33-D33 -> 38648 | F33: =IFERROR(E33/ABS(D33),"n.s.") -> n.s.
A34: Riserva per strumenti finanziari derivati al fair value | C34: -873 | D34: -692 | E34: =C34-D34 -> -181 | F34: =IFERROR(E34/ABS(D34),"n.s.") -> -0.26156069
A35: Differenza da conversione dei bilanci in valuta estera | C35: 317 | D35: 2323 | E35: =C35-D35 -> -2006 | F35: =IFERROR(E35/ABS(D35),"n.s.") -> -0.86353853
A36: Altre riserve | C36: 8194 | D36: 7786 | E36: =C36-D36 -> 408 | F36: =IFERROR(E36/ABS(D36),"n.s.") -> 0.052401747
A37: Riserva First Time Adoption | C37: 8953 | D37: 8953 | E37: =C37-D37 -> 0 | F37: =IFERROR(E37/ABS(D37),"n.s.") -> 0
A38: Utili indivisi | C38: 231717 | D38: 232774 | E38: =C38-D38 -> -1057 | F38: =IFERROR(E38/ABS(D38),"n.s.") -> -0.0045408852
A39: Risultato netto dell'esercizio | C39: ='Conto Economico'!C18 -> 39655 | D39: ='Conto Economico'!D18 -> 42116 | E39: =C39-D39 -> -2461 | F39: =IFERROR(E39/ABS(D39),"n.s.") -> -0.058433849
A40: Acconto sul dividendo | C40: 0 | D40: 0 | E40: =C40-D40 -> 0 | F40: =IFERROR(E40/ABS(D40),"n.s.") -> n.s.
A41: Totale patrimonio netto | B41: 4.13 | C41: =SUM(C30:C40) -> 362731 | D41: =SUM(D30:D40) -> 329380 | E41: =C41-D41 -> 33351 | F41: =IFERROR(E41/ABS(D41),"n.s.") -> 0.10125387
A43: Passività non correnti
A44: Finanziamenti dovuti oltre un anno | B44: 4.14 | C44: 273941 | D44: 203334 | E44: =C44-D44 -> 70607 | F44: =IFERROR(E44/ABS(D44),"n.s.") -> 0.3472464
...

Sheet Conto Economico
A1: FIDIA FARMACEUTICI S.p.A. — Income Statement
A2: Conto Economico Consolidato — valori in migliaia di Euro, salvo diversa indicazione | V2: Tabella di supporto ai grafici
V3: Anno | W3: Fatturato | X3: EBITDA | Y3: EBIT | Z3: Utile Netto
A4: 1. CONTO ECONOMICO CONSOLIDATO IFRS (schema per destinazione di costo, ai sensi IAS 1) | V4: 2021 | W4: =B54 -> 358539 | X4: =B65 -> 65971.176 | Y4: =B66 -> 53780.85 | Z4: =B67 -> 36471
A5: Voce | B5: Nota | C5: 31/12/2025 | D5: 31/12/2024 | E5: Variazione | F5: Var % | V5: 2022 | W5: =C54 -> 412074 | X5: =C65 -> 80354.43 | Y5: =C66 -> 51509.25 | Z5: =C67 -> 37832
A6: Ricavi netti | B6: 5.1 | C6: 538343 | D6: 510120 | E6: =C6-D6 -> 28223 | F6: =IFERROR(E6/ABS(D6),"n.s.") -> 0.055326198 | V6: 2023 | W6: =D54 -> 454199 | X6: =D65 -> 89477.203 | Y6: =D66 -> 62679.462 | Z6: =D67 -> 45236
A7: Costo del venduto | B7: 5.2 | C7: -215762 | D7: -200087 | E7: =C7-D7 -> -15675 | F7: =IFERROR(E7/ABS(D7),"n.s.") -> -0.078340922 | V7: 2024 | W7: =E54 -> 510120 | X7: =E65 -> 97513 | Y7: =E66 -> 68986 | Z7: =E67 -> 42116
A8: Risultato operativo lordo (Gross Profit) | C8: =C6+C7 -> 322581 | D8: =D6+D7 -> 310033 | E8: =C8-D8 -> 12548 | F8: =IFERROR(E8/ABS(D8),"n.s.") -> 0.040473111 | V8: 2025 | W8: =F54 -> 538343 | X8: =F65 -> 110124 | Y8: =F66 -> 60138 | Z8: =F67 -> 39655
A9: Spese di vendita | B9: 5.2 | C9: -153011 | D9: -150063 | E9: =C9-D9 -> -2948 | F9: =IFERROR(E9/ABS(D9),"n.s.") -> -0.019645082
A10: Spese di ricerca e sviluppo | B10: 5.2 | C10: -41733 | D10: -29285 | E10: =C10-D10 -> -12448 | F10: =IFERROR(E10/ABS(D10),"n.s.") -> -0.42506403
A11: Spese generali e amministrative | B11: 5.2 | C11: -69055 | D11: -63039 | E11: =C11-D11 -> -6016 | F11: =IFERROR(E11/ABS(D11),"n.s.") -> -0.095432986 | V11: Tabella di supporto ai grafici
A12: Altri (oneri)/proventi netti | B12: 5.2 | C12: 1356 | D12: 1340 | E12: =C12-D12 -> 16 | F12: =IFERROR(E12/ABS(D12),"n.s.") -> 0.011940299 | V12: Anno | W12: ROS | X12: MOL/Ricavi | Y12: ROA | Z12: ROE
A13: Totale costi operativi | C13: =SUM(C9:C12) -> -262443 | D13: =SUM(D9:D12) -> -241047 | E13: =C13-D13 -> -21396 | F13: =IFERROR(E13/ABS(D13),"n.s.") -> -0.088762772 | V13: 2021 | W13: =B58 -> 0.15 | X13: =B59 -> 0.184 | Y13: =B60 -> 0.094 | Z13: =B61 -> 0.172
A14: RISULTATO OPERATIVO (EBIT) | C14: =C8+C13 -> 60138 | D14: =D8+D13 -> 68986 | E14: =C14-D14 -> -8848 | F14: =IFERROR(E14/ABS(D14),"n.s.") -> -0.12825791 | V14: 2022 | W14: =C58 -> 0.125 | X14: =C59 -> 0.195 | Y14: =C60 -> 0.081 | Z14: =C61 -> 0.148
A15: (Oneri)/proventi finanziari netti | B15: 5.3 | C15: -13728 | D15: -5299 | E15: =C15-D15 -> -8429 | F15: =IFERROR(E15/ABS(D15),"n.s.") -> -1.5906775 | V15: 2023 | W15: =D58 -> 0.138 | X15: =D59 -> 0.197 | Y15: =D60 -> 0.096 | Z15: =D61 -> 0.155
A16: Risultato prima delle imposte | C16: =C14+C15 -> 46410 | D16: =D14+D15 -> 63687 | E16: =C16-D16 -> -17277 | F16: =IFERROR(E16/ABS(D16),"n.s.") -> -0.27127985 | V16: 2024 | W16: =E58 -> 0.13523485 | X16: =E59 -> 0.19115698 | Y16: =E60 -> 0.086497832 | Z16: =E61 -> 0.12786447
A17: Imposte | B17: 5.4 | C17: -6755 | D17: -21571 | E17: =C17-D17 -> 14816 | F17: =IFERROR(E17/ABS(D17),"n.s.") -> 0.68684808 | V17: 2025 | W17: =F58 -> 0.11170945 | X17: =F59 -> 0.20456103 | Y17: =F60 -> 0.071450891 | Z17: =F61 -> 0.10932344
A18: UTILE NETTO DELL'ESERCIZIO | C18: =C16+C17 -> 39655 | D18: =D16+D17 -> 42116 | E18: =C18-D18 -> -2461 | F18: =IFERROR(E18/ABS(D18),"n.s.") -> -0.058433849
A20: Dati complementari (fonte: Relazione sulla Gestione — Principali dati economici consolidati)
A21: di cui: Ammortamenti e svalutazioni | C21: -49986 | D21: -28527 | E21: =C21-D21 -> -21459 | F21: =IFERROR(E21/ABS(D21),"n.s.") -> -0.75223472
A22: EBITDA (Margine Operativo Lordo) | C22: =C14-C21 -> 110124 | D22: =D14-D21 -> 97513 | E22: =C22-D22 -> 12611 | F22: =IFERROR(E22/ABS(D22),"n.s.") -> 0.12932635
A23: EBITDA margin (EBITDA / Ricavi netti) | C23: =C22/C6 -> 0.20456103 | D23: =D22/D6 -> 0.19115698
A25: Fonte: Fidia Farmaceutici S.p.A., Bilancio Consolidato al 31/12/2025, «Conto Economico Consolidato», pag. 74/89 (Note 5.1-5.4), e Relazione sulla Gestione — «Principali dati economici consolidati», pag. 51/89 (per Ammortamenti/EBITDA). Valori in migliaia di Euro. Il totale «Risultato operativo» ricalcolato per formula (C14) può differire di ±1 migliaia di Euro dal dato pubblicato per arrotondamento.
A28: 2. CONTO ECONOMICO RICLASSIFICATO — METODO ICAS (a valore aggiunto / EBITDA)
A29: Voce | B29: Nota | C29: 31/12/2025 | D29: 31/12/2024 | E29: Variazione | F29: Var %
A30: Valore della produzione (Ricavi netti) | C30: =C6 -> 538343 | D30: =D6 -> 510120 | E30: =C30-D30 -> 28223 | F30: =IFERROR(E30/ABS(D30),"n.s.") -> 0.055326198
A31: Costi della produzione (mat. prime, servizi, personale — stima da ponte EBITDA) | C31: =-(C30-C22) -> -428219 | D31: =-(D30-D22) -> -412607 | E31: =C31-D31 -> -15612 | F31: =IFERROR(E31/ABS(D31),"n.s.") -> -0.037837458
A32: MOL / EBITDA (Margine Operativo Lordo) | C32: =C30+C31 -> 110124 | D32: =D30+D31 -> 97513 | E32: =C32-D32 -> 12611 | F32: =IFERROR(E32/ABS(D32),"n.s.") -> 0.12932635
A33: Ammortamenti, svalutazioni e accantonamenti | C33: =C21 -> -49986 | D33: =D21 -> -28527 | E33: =C33-D33 -> -21459 | F33: =IFERROR(E33/ABS(D33),"n.s.") -> -0.75223472
A34: EBIT (Risultato Operativo) | C34: =C32+C33 -> 60138 | D34: =D32+D33 -> 68986 | E34: =C34-D34 -> -8848 | F34: =IFERROR(E34/ABS(D34),"n.s.") -> -0.12825791
A35: Proventi/(oneri) della gestione finanziaria | C35: =C15 -> -13728 | D35: =D15 -> -5299 | E35: =C35-D35 -> -8429 | F35: =IFERROR(E35/ABS(D35),"n.s.") -> -1.5906775
A36: Risultato ante imposte (EBT) | C36: =C34+C35 -> 46410 | D36: =D34+D35 -> 63687 | E36: =C36-D36 -> -17277 | F36: =IFERROR(E36/ABS(D36),"n.s.") -> -0.27127985
A37: Imposte sul reddito | C37: =C17 -> -6755 | D37: =D17 -> -21571 | E37: =C37-D37 -> 14816 | F37: =IFERROR(E37/ABS(D37),"n.s.") -> 0.68684808
A38: RISULTATO NETTO | C38: =C36+C37 -> 39655 | D38: =D36+D37 -> 42116 | E38: =C38-D38 -> -2461 | F38: =IFERROR(E38/ABS(D38),"n.s.") -> -0.058433849
A40: 3. INDICATORI DI REDDITIVITÀ ICAS
A41: Indicatore | C41: 31/12/2025 | D41: 31/12/2024 | E41: Variazione
A42: MOL margin (MOL / Ricavi netti) | C42: =C32/C30 -> 0.20456103 | D42: =D32/D30 -> 0.19115698 | E42: =C42-D42 -> 0.01340405 | F42: =IFERROR(E42/ABS(D42),"n.s.") -> 0.07012064
A43: EBITDA margin | C43: =C22/C6 -> 0.20456103 | D43: =D22/D6 -> 0.19115698 | E43: =C43-D43 -> 0.01340405 | F43: =IFERROR(E43/ABS(D43),"n.s.") -> 0.07012064
A44: ROS — Return on Sales (EBIT / Ricavi netti) | C44: =C34/C30 -> 0.11170945 | D44: =D34/D30 -> 0.13523485 | E44: =C44-D44 -> -0.023525398 | F44: =IFERROR(E44/ABS(D44),"n.s.") -> -0.17395958
A45: Asset Turnover (Ricavi netti / Totale Attivo) | C45: =C30/'Stato Patrimoniale'!C26 -> 0.63961367 | D45: =D30/'Stato Patrimoniale'!D26 -> 0.63961201 | E45: =C45-D45 -> 1.662518e-06 | F45: =IFERROR(E45/ABS(D45),"n.s.") -> 2.5992601e-06
...

Sheet Rendiconto Finanziario
A1: FIDIA FARMACEUTICI S.p.A. — Cash Flow Statement
A2: Rendiconto Finanziario Consolidato — valori in migliaia di Euro, salvo diversa indicazione | V2: Tabella di supporto ai grafici
V3: Anno | W3: CFO | X3: CFI | Y3: CFF | Z3: Variazione Netta
A4: 1. RENDICONTO FINANZIARIO CONSOLIDATO IFRS (metodo indiretto) | V4: 2024 | W4: =E83 -> 41644 | X4: =E84 -> -210023 | Y4: =E85 -> 75605 | Z4: =E86 -> -92774
A5: Voce | C5: 2025 | D5: 2024 | E5: Variazione | F5: Var % | V5: 2025 | W5: =F83 -> 74510 | X5: =F84 -> -97977 | Y5: =F85 -> 12379 | Z5: =F86 -> -11088
A6: Flussi finanziari derivanti dall'attività di gestione
A7: Risultato netto dell'esercizio | C7: ='Conto Economico'!C18 -> 39655 | D7: ='Conto Economico'!D18 -> 42116 | E7: =C7-D7 -> -2461 | F7: =IFERROR(E7/ABS(D7),"n.s.") -> -0.058433849
A8: Imposte sul reddito | C8: 6755 | D8: 21571 | E8: =C8-D8 -> -14816 | F8: =IFERROR(E8/ABS(D8),"n.s.") -> -0.68684808 | V8: Tabella di supporto ai grafici
A9: Proventi e oneri finanziari | C9: 12393 | D9: 5715 | E9: =C9-D9 -> 6678 | F9: =IFERROR(E9/ABS(D9),"n.s.") -> 1.1685039 | V9: Anno | W9: Utile Netto
A10: (Plusvalenze)/minusvalenze derivanti dalla cessione di attività | C10: 8 | D10: 664 | E10: =C10-D10 -> -656 | F10: =IFERROR(E10/ABS(D10),"n.s.") -> -0.98795181 | V10: 2021 | W10: =B80 -> 36471
A11: Accantonamenti e utilizzo fondi | C11: -801 | D11: -1756 | E11: =C11-D11 -> 955 | F11: =IFERROR(E11/ABS(D11),"n.s.") -> 0.54384966 | V11: 2022 | W11: =C80 -> 37832
A12: Ammortamenti delle immobilizzazioni | C12: 44140 | D12: 27293 | E12: =C12-D12 -> 16847 | F12: =IFERROR(E12/ABS(D12),"n.s.") -> 0.6172645 | V12: 2023 | W12: =D80 -> 45236
A13: Svalutazioni per perdite durevoli di valore | C13: 1855 | D13: 297 | E13: =C13-D13 -> 1558 | F13: =IFERROR(E13/ABS(D13),"n.s.") -> 5.2457912 | V13: 2024 | W13: =E80 -> 42116
A14: Altre rettifiche per elementi non monetari | C14: 6719 | D14: 0 | E14: =C14-D14 -> 6719 | F14: =IFERROR(E14/ABS(D14),"n.s.") -> n.s. | V14: 2025 | W14: =F80 -> 39655
A15: Imposte sul reddito pagate | C15: -12911 | D15: -15312 | E15: =C15-D15 -> 2401 | F15: =IFERROR(E15/ABS(D15),"n.s.") -> 0.15680512
A16: Interessi pagati | C16: -11948 | D16: -6412 | E16: =C16-D16 -> -5536 | F16: =IFERROR(E16/ABS(D16),"n.s.") -> -0.86338116
A17: Flusso finanziario prima delle variazioni del CCN | C17: =SUM(C7:C16) -> 85865 | D17: =SUM(D7:D16) -> 74176 | E17: =C17-D17 -> 11689 | F17: =IFERROR(E17/ABS(D17),"n.s.") -> 0.15758466
A19: Capitale circolante
A20: Variazione crediti verso clienti | C20: 6201 | D20: -22368 | E20: =C20-D20 -> 28569 | F20: =IFERROR(E20/ABS(D20),"n.s.") -> 1.2772264
A21: Variazione rimanenze di magazzino | C21: 1222 | D21: -20394 | E21: =C21-D21 -> 21616 | F21: =IFERROR(E21/ABS(D21),"n.s.") -> 1.0599196
A22: Variazione altri crediti e altre attività correnti | C22: -3050 | D22: -8479 | E22: =C22-D22 -> 5429 | F22: =IFERROR(E22/ABS(D22),"n.s.") -> 0.64028777
A23: Variazione dei debiti verso fornitori | C23: -11673 | D23: 7018 | E23: =C23-D23 -> -18691 | F23: =IFERROR(E23/ABS(D23),"n.s.") -> -2.6632944
A24: Variazione altri debiti e altre passività correnti | C24: -1824 | D24: -4509 | E24: =C24-D24 -> 2685 | F24: =IFERROR(E24/ABS(D24),"n.s.") -> 0.59547572
A25: Variazione dei ratei e risconti attivi e passivi | C25: -2231 | D25: 16200 | E25: =C25-D25 -> -18431 | F25: =IFERROR(E25/ABS(D25),"n.s.") -> -1.137716
A26: Variazione dei crediti verso controllante | C26: 0 | D26: 0 | E26: =C26-D26 -> 0 | F26: =IFERROR(E26/ABS(D26),"n.s.") -> n.s.
A27: Variazione del capitale circolante | C27: =SUM(C20:C26) -> -11355 | D27: =SUM(D20:D26) -> -32532 | E27: =C27-D27 -> 21177 | F27: =IFERROR(E27/ABS(D27),"n.s.") -> 0.65095906
A28: DISPONIBILITÀ LIQUIDE GENERATE/(ASSORBITE) DALL'ATTIVITÀ DI GESTIONE | C28: =C17+C27 -> 74510 | D28: =D17+D27 -> 41644 | E28: =C28-D28 -> 32866 | F28: =IFERROR(E28/ABS(D28),"n.s.") -> 0.78921333
A30: Flussi finanziari derivanti dall'attività di investimento
A31: Investimenti netti in immobilizzazioni materiali | C31: -25490 | D31: -25476 | E31: =C31-D31 -> -14 | F31: =IFERROR(E31/ABS(D31),"n.s.") -> -0.00054953682
A32: Investimenti netti in immobilizzazioni immateriali | C32: -21133 | D32: -184303 | E32: =C32-D32 -> 163170 | F32: =IFERROR(E32/ABS(D32),"n.s.") -> 0.88533556
A33: Investimenti in immobilizzazioni finanziarie | C33: -38337 | D33: -244 | E33: =C33-D33 -> -38093 | F33: =IFERROR(E33/ABS(D33),"n.s.") -> -156.11885
A34: Acquisizione di partecipazioni | C34: -13017 | D34: 0 | E34: =C34-D34 -> -13017 | F34: =IFERROR(E34/ABS(D34),"n.s.") -> n.s.
A35: DISPONIBILITÀ LIQUIDE GENERATE/(ASSORBITE) DALL'ATTIVITÀ DI INVESTIMENTO | C35: =SUM(C31:C34) -> -97977 | D35: =SUM(D31:D34) -> -210023 | E35: =C35-D35 -> 112046 | F35: =IFERROR(E35/ABS(D35),"n.s.") -> 0.53349395
A37: Flussi finanziari derivanti dall'attività di finanziamento
A38: Accensione finanziamenti | C38: 62906 | D38: 129675 | E38: =C38-D38 -> -66769 | F38: =IFERROR(E38/ABS(D38),"n.s.") -> -0.51489493
A39: Rimborso finanziamenti | C39: -44739 | D39: -51739 | E39: =C39-D39 -> 7000 | F39: =IFERROR(E39/ABS(D39),"n.s.") -> 0.13529446
A40: Pagamento passività per leasing | C40: 336 | D40: -357 | E40: =C40-D40 -> 693 | F40: =IFERROR(E40/ABS(D40),"n.s.") -> 1.9411765
A41: Variazione debiti verso banche | C41: 0 | D41: 0 | E41: =C41-D41 -> 0 | F41: =IFERROR(E41/ABS(D41),"n.s.") -> n.s.
A42: Altre variazioni di patrimonio netto | C42: -2124 | D42: 1026 | E42: =C42-D42 -> -3150 | F42: =IFERROR(E42/ABS(D42),"n.s.") -> -3.0701754
A43: Dividendi distribuiti | C43: -4000 | D43: -3000 | E43: =C43-D43 -> -1000 | F43: =IFERROR(E43/ABS(D43),"n.s.") -> -0.33333333
...
